Workbook
Name Administrative_Financial_and_Management_Service: DV!$AI$16:$AI$20
Name dropdown: RCA!$H$3:$H$100
Name Fakelist: DV!$AI$22:$AI$23
Name Legal_Service: DV!$AJ$16:$AJ$20
Name Local_Fiscal_Policy_Service: DV!$AK$16:$AK$20
Name Local_Government_Units_Operations_Service: DV!$AL$16:$AL$20
Name RCA_List: OFFSET(RCA!$H$3,,,COUNTIF(RCA!XFD:XFD,"?*"))
Name RespCtr: DV!$AI$15:$AL$15

Sheet DV
AA1: Appendix 32
A3: BUREAU OF LOCAL GOVERNMENT FINANCE | AA3: Fund Cluster :
A4: Entity Name | AA4: Regular Agency Fund
A5: DISBURSEMENT VOUCHER | AA5: Date : | AC5: =TODAY() -> 42396 | AI5: Regular Agency Fund
AA6: DV No. : | AI6: Business Related Fund
AA7: =NOW() -> 42396.685
A8: Mode of Payment
G9: MDS Check | L9: Commercial Check | S9: LDDAP-ADA | X9: Others (Please specify)
Z10: _________________
A11: Payee | R11: TIN/Employee No.: | AA11: ORS/BURS No.:
A13: Address
A15: Particulars | Q15: Responsibility Center | V15: MFO/PAP | AA15: Amount | AI15: Administrative Financial and Management Service | AJ15: Legal Service | AK15: Local Fiscal Policy Service | AL15: Local Government Units Operations Service
AI16: Financial and Management Division | AJ16: Legal Division | AK16: Policy, Planning, Programming and Standards Division | AL16: Local Assessment Operation Division
AI17: Administrative Division | AJ17: Internal Affairs Division | AK17: Local Financial Data Analysis Division | AL17: Local Treasury Operations Division
AI18: Information Systems Management Division | AK18: Local Debt Monitoring and Evaluation Division | AL18: Project Execution & Management Division
AL20: Capacity Building Division
A24: Amount Due
A25: A. | B25: Certified: Expenses/Cash Advance necessary, lawful and incurred under my direct supervision.
A26: ____________________________________________________________
A28: Printed Name, Designation and Signature of Supervisor
A30: B. | B30: Accounting Entry:
A31: Account Title | R31: UACS Code | W31: Debit | AB31: Credit
R32: =IFERROR(INDEX(RCA!A:A,MATCH(DV!A32,RCA!F:F,0)),"")
R33: =IFERROR(INDEX(RCA!A:A,MATCH(DV!A33,RCA!F:F,0)),"")
A34: Traveling Expenses-Local | R34: =IFERROR(INDEX(RCA!A:A,MATCH(DV!A34,RCA!F:F,0)),"") -> 5020101000 | W34: =AA24 -> 0
R35: =IFERROR(INDEX(RCA!A:A,MATCH(DV!A35,RCA!F:F,0)),"")
A36: =IF($AA$4="Regular Agency Fund",RCA!$F$70,RCA!$F$45) -> Cash-Modified Disbursement System (MDS), Regular | R36: =IFERROR(INDEX(RCA!A:A,MATCH(DV!A36,RCA!F:F,0)),"") -> 1010404000 | AB36: =AA24 -> 0
R37: =IFERROR(INDEX(RCA!A:A,MATCH(DV!A37,RCA!F:F,0)),"")
R38: =IFERROR(INDEX(RCA!A:A,MATCH(DV!A38,RCA!F:F,0)),"")
A39: C. | B39: Certified: | R39: D. | S39: Approved for Payment
C41: Cash available
C43: Subject to Authority to Debit Account (when applicable)
C45: Supporting documents complete and amount claimed proper
A47: Signature | R47: Signature
A49: Printed Name | D49: JO ANN T. MENDOZA | R49: Printed Name | V49: JOCELYN T. PENDON
A50: Position | D50: Accountant III | R50: Position | V50: =IF(V49=AI50,AJ50,IF(V49=AI51,AJ51,IF(V49=AI52,AJ52,IF(V49=AI53,AJ53,"")))) -> OIC-Executive Director | AI50: JOCELYN T. PENDON | AJ50: OIC-Executive Director
A51: Date | R51: Date | AI51: Atty. FLOSIE F. FANLO-TAYAG, CESO IV | AJ51: Deputy Executive Director for Administration
A52: E. | B52: Receipt of Payment | AA52: JEV No. | AI52: JOSE ARNOLD M. TAN, CESO V | AJ52: Director II, Policy Enforcement Service
A53: Check/ ADA No. : | M53: Date : | R53: Bank Name & Account Number: | AI53: ARMI M. ADVINCULA | AJ53: Director II, Internal Administration Office
A55: Signature : | M55: Date : | R55: Printed Name: | AA55: Date
...

Sheet RCA
A1: UACS | B1: Check Duplicates | C1: Object Code | D1: RCA | E1: Column1 | F1: Account Title | I1: =CELL("contents") -> 0
A3: 1010101000 | B3: 10101010 | C3: =RIGHT(Table1[[#This Row],[UACS]],2)*1 -> 0 | D3: 10101010 | E3: =IF(ISNUMBER(SEARCH($I$1,F3)),MAX($E$2:E2)+1,0) -> 0 | F3: Cash-Collecting Officers | H3: =IFERROR(VLOOKUP(ROWS($H$3:H3),$E$3:$F$1136,2,0),"") -> Share from National Wealth-Tobacco Excise Tax (Burley and Native) per R.A. 8240 | I3: IFERROR(VLOOKUP(ROWS($C$2:C2),$A$2:$B$635,2,0),"")
A4: 1010102000 | B4: 10101020 | C4: =RIGHT(Table1[[#This Row],[UACS]],2)*1 -> 0 | D4: 10101020 | E4: =IF(ISNUMBER(SEARCH($I$1,F4)),MAX($E$2:E3)+1,0) -> 0 | F4: Petty Cash | H4: =IFERROR(VLOOKUP(ROWS($H$3:H4),$E$3:$F$1136,2,0),"") -> Share from National Wealth-Mining Taxes per R.A. 7160
A5: 1010201000 | B5: 10102010 | C5: =RIGHT(Table1[[#This Row],[UACS]],2)*1 -> 0 | D5: 10102010 | E5: =IF(ISNUMBER(SEARCH($I$1,F5)),MAX($E$2:E4)+1,0) -> 0 | F5: Cash in Bank-Local Currency, Bangko Sentral ng Pilipinas | H5: =IFERROR(VLOOKUP(ROWS($H$3:H5),$E$3:$F$1136,2,0),"") -> Share from National Wealth-Royalties per R.A. 7160
A6: 1010202001 | B6: 10102020 | C6: =RIGHT(Table1[[#This Row],[UACS]],2)*1 -> 1 | D6: 10102020 | E6: =IF(ISNUMBER(SEARCH($I$1,F6)),MAX($E$2:E5)+1,0) -> 0 | F6: Cash in Bank-Local Currency, Current Account-Allied Bank | H6: =IFERROR(VLOOKUP(ROWS($H$3:H6),$E$3:$F$1136,2,0),"") -> Share from National Wealth-Forestry Charges per R.A. 7160
A7: 1010202002 | B7: 10102020 | C7: =RIGHT(Table1[[#This Row],[UACS]],2)*1 -> 2 | D7: 10102020 | E7: =IF(ISNUMBER(SEARCH($I$1,F7)),MAX($E$2:E6)+1,0) -> 0 | F7: Cash in Bank-Local Currency, Current Account-Amanah Bank | H7: =IFERROR(VLOOKUP(ROWS($H$3:H7),$E$3:$F$1136,2,0),"") -> Share from National Wealth-Fishery Charges per R.A. 7160
A8: 1010202003 | B8: 10102020 | C8: =RIGHT(Table1[[#This Row],[UACS]],2)*1 -> 3 | D8: 10102020 | E8: =IF(ISNUMBER(SEARCH($I$1,F8)),MAX($E$2:E7)+1,0) -> 0 | F8: Cash in Bank-Local Currency, Current Account-Asia United Bank Corporation | H8: =IFERROR(VLOOKUP(ROWS($H$3:H8),$E$3:$F$1136,2,0),"") -> Share from National Wealth-Value Added Tax in lieu of Franchise Tax per R.A. 7953 and R.A. 8407
A9: 1010202004 | B9: 10102020 | C9: =RIGHT(Table1[[#This Row],[UACS]],2)*1 -> 4 | D9: 10102020 | E9: =IF(ISNUMBER(SEARCH($I$1,F9)),MAX($E$2:E8)+1,0) -> 0 | F9: Cash in Bank-Local Currency, Current Account-Australia and New Zealand Bank | H9: =IFERROR(VLOOKUP(ROWS($H$3:H9),$E$3:$F$1136,2,0),"") -> Subsistence Allowance-Magna Carta Benefits for Public Health Workers under R.A. 7305
A10: 1010202005 | B10: 10102020 | C10: =RIGHT(Table1[[#This Row],[UACS]],2)*1 -> 5 | D10: 10102020 | E10: =IF(ISNUMBER(SEARCH($I$1,F10)),MAX($E$2:E9)+1,0) -> 0 | F10: Cash in Bank-Local Currency, Current Account-Banco de Oro (BDO) | H10: =IFERROR(VLOOKUP(ROWS($H$3:H10),$E$3:$F$1136,2,0),"") -> Laundry Allowance-Magna Carta Benefits for Public Health Workers under R.A. 7305
A11: 1010202006 | B11: 10102020 | C11: =RIGHT(Table1[[#This Row],[UACS]],2)*1 -> 6 | D11: 10102020 | E11: =IF(ISNUMBER(SEARCH($I$1,F11)),MAX($E$2:E10)+1,0) -> 0 | F11: Cash in Bank-Local Currency, Current Account-Bangkok Bank | H11: =IFERROR(VLOOKUP(ROWS($H$3:H11),$E$3:$F$1136,2,0),"") -> Quarters Allowance-Magna Carta Benefits for Public Health Workers under R.A. 7305
A12: 1010202007 | B12: 10102020 | C12: =RIGHT(Table1[[#This Row],[UACS]],2)*1 -> 7 | D12: 10102020 | E12: =IF(ISNUMBER(SEARCH($I$1,F12)),MAX($E$2:E11)+1,0) -> 0 | F12: Cash in Bank-Local Currency, Current Account-Bangkok Bank Public Company Limited | H12: =IFERROR(VLOOKUP(ROWS($H$3:H12),$E$3:$F$1136,2,0),"") -> Honoraria-Magna Carta Benefits for Public Health Workers under R.A. 7305
A13: 1010202008 | B13: 10102020 | C13: =RIGHT(Table1[[#This Row],[UACS]],2)*1 -> 8 | D13: 10102020 | E13: =IF(ISNUMBER(SEARCH($I$1,F13)),MAX($E$2:E12)+1,0) -> 0 | F13: Cash in Bank-Local Currency, Current Account-Bank of China | H13: =IFERROR(VLOOKUP(ROWS($H$3:H13),$E$3:$F$1136,2,0),"") -> HP-Magna Carta Benefits for Public Health Workers under R.A. 7305
A14: 1010202009 | B14: 10102020 | C14: =RIGHT(Table1[[#This Row],[UACS]],2)*1 -> 9 | D14: 10102020 | E14: =IF(ISNUMBER(SEARCH($I$1,F14)),MAX($E$2:E13)+1,0) -> 0 | F14: Cash in Bank-Local Currency, Current Account-Bank of Commerce | H14: =IFERROR(VLOOKUP(ROWS($H$3:H14),$E$3:$F$1136,2,0),"") -> Longevity Pay-Magna Carta Benefits for Public Health Workers under R.A. 7305
A15: 1010202010 | B15: 10102020 | C15: =RIGHT(Table1[[#This Row],[UACS]],2)*1 -> 10 | D15: 10102020 | E15: =IF(ISNUMBER(SEARCH($I$1,F15)),MAX($E$2:E14)+1,0) -> 0 | F15: Cash in Bank-Local Currency, Current Account-Bank of the Philippine Islands (BPI) | H15: =IFERROR(VLOOKUP(ROWS($H$3:H15),$E$3:$F$1136,2,0),"") -> Lump-sum for NBC No. 308
... A20: 1010202015 | B20: 10102020 | C20: =RIGHT(Table1[[#This Row],[UACS]],2)*1 -> 15 | D20: 10102020 | E20: =IF(ISNUMBER(SEARCH($I$1,F20)),MAX($E$2:E19)+1,0) -> 0 | F20: Cash in Bank-Local Currency, Current Account-Deutsche Bank AG | H20: =IFERROR(VLOOKUP(ROWS($H$3:H20),$E$3:$F$1136,2,0),"") -> Financial Assistance to LGUs-Fishery Charges per R.A. 7160
A21: 1010202016 | B21: 10102020 | C21: =RIGHT(Table1[[#This Row],[UACS]],2)*1 -> 16 | D21: 10102020 | E21: =IF(ISNUMBER(SEARCH($I$1,F21)),MAX($E$2:E20)+1,0) -> 0 | F21: Cash in Bank-Local Currency, Current Account-Development Bank of the Philippines (DBP) | H21: =IFERROR(VLOOKUP(ROWS($H$3:H21),E:F,2,0),"") -> Financial Assistance to LGUs-Value Added Tax in lieu of Franchise Tax per R.A. 7953 and R.A. 8407
A22: 1010202017 | B22: 10102020 | C22: =RIGHT(Table1[[#This Row],[UACS]],2)*1 -> 17 | D22: 10102020 | E22: =IF(ISNUMBER(SEARCH($I$1,F22)),MAX($E$2:E21)+1,0) -> 0 | F22: Cash in Bank-Local Currency, Current Account-East-West Banking Corporation | H22: =IFERROR(VLOOKUP(ROWS($H$3:H22),E:F,2,0),"")
A23: 1010202018 | B23: 10102020 | C23: =RIGHT(Table1[[#This Row],[UACS]],2)*1 -> 18 | D23: 10102020 | E23: =IF(ISNUMBER(SEARCH($I$1,F23)),MAX($E$2:E22)+1,0) -> 0 | F23: Cash in Bank-Local Currency, Current Account-Equitable PCI Bank | H23: =IFERROR(VLOOKUP(ROWS($H$3:H23),E:F,2,0),"")
A24: 1010202019 | B24: 10102020 | C24: =RIGHT(Table1[[#This Row],[UACS]],2)*1 -> 19 | D24: 10102020 | E24: =IF(ISNUMBER(SEARCH($I$1,F24)),MAX($E$2:E23)+1,0) -> 0 | F24: Cash in Bank-Local Currency, Current Account-First Consolidated Bank (FCB) | H24: =IFERROR(VLOOKUP(ROWS($H$3:H24),E:F,2,0),"")
A25: 1010202020 | B25: 10102020 | C25: =RIGHT(Table1[[#This Row],[UACS]],2)*1 -> 20 | D25: 10102020 | E25: =IF(ISNUMBER(SEARCH($I$1,F25)),MAX($E$2:E24)+1,0) -> 0 | F25: Cash in Bank-Local Currency, Current Account-Fuji-Mizuho Bank | H25: =IFERROR(VLOOKUP(ROWS($H$3:H25),E:F,2,0),"")
A26: 1010202021 | B26: 10102020 | C26: =RIGHT(Table1[[#This Row],[UACS]],2)*1 -> 21 | D26: 10102020 | E26: =IF(ISNUMBER(SEARCH($I$1,F26)),MAX($E$2:E25)+1,0) -> 0 | F26: Cash in Bank-Local Currency, Current Account-Hong Kong and Shanghai Banking Corp | H26: =IFERROR(VLOOKUP(ROWS($H$3:H26),E:F,2,0),"")
A27: 1010202022 | B27: 10102020 | C27: =RIGHT(Table1[[#This Row],[UACS]],2)*1 -> 22 | D27: 10102020 | E27: =IF(ISNUMBER(SEARCH($I$1,F27)),MAX($E$2:E26)+1,0) -> 0 | F27: Cash in Bank-Local Currency, Current Account-International Commercial Bank of China | H27: =IFERROR(VLOOKUP(ROWS($H$3:H27),E:F,2,0),"")
A28: 1010202023 | B28: 10102020 | C28: =RIGHT(Table1[[#This Row],[UACS]],2)*1 -> 23 | D28: 10102020 | E28: =IF(ISNUMBER(SEARCH($I$1,F28)),MAX($E$2:E27)+1,0) -> 0 | F28: Cash in Bank-Local Currency, Current Account-International Exchange Bank | H28: =IFERROR(VLOOKUP(ROWS($H$3:H28),E:F,2,0),"")
A29: 1010202024 | B29: 10102020 | C29: =RIGHT(Table1[[#This Row],[UACS]],2)*1 -> 24 | D29: 10102020 | E29: =IF(ISNUMBER(SEARCH($I$1,F29)),MAX($E$2:E28)+1,0) -> 0 | F29: Cash in Bank-Local Currency, Current Account-Land Bank of the Philippines ( LBP) | H29: =IFERROR(VLOOKUP(ROWS($H$3:H29),E:F,2,0),"")
A30: 1010202025 | B30: 10102020 | C30: =RIGHT(Table1[[#This Row],[UACS]],2)*1 -> 25 | D30: 10102020 | E30: =IF(ISNUMBER(SEARCH($I$1,F30)),MAX($E$2:E29)+1,0) -> 0 | F30: Cash in Bank-Local Currency, Current Account-Maybank Philippines | H30: =IFERROR(VLOOKUP(ROWS($H$3:H30),E:F,2,0),"")
A31: 1010202026 | B31: 10102020 | C31: =RIGHT(Table1[[#This Row],[UACS]],2)*1 -> 26 | D31: 10102020 | E31: =IF(ISNUMBER(SEARCH($I$1,F31)),MAX($E$2:E30)+1,0) -> 0 | F31: Cash in Bank-Local Currency, Current Account-Metropolitan and Trust Co | H31: =IFERROR(VLOOKUP(ROWS($H$3:H31),E:F,2,0),"")
A32: 1010202027 | B32: 10102020 | C32: =RIGHT(Table1[[#This Row],[UACS]],2)*1 -> 27 | D32: 10102020 | E32: =IF(ISNUMBER(SEARCH($I$1,F32)),MAX($E$2:E31)+1,0) -> 0 | F32: Cash in Bank-Local Currency, Current Account-Philippine Bank of Communications | H32: =IFERROR(VLOOKUP(ROWS($H$3:H32),E:F,2,0),"")
... A1136: 5050499000 | B1136: 50504990 | C1136: =RIGHT(Table1[[#This Row],[UACS]],2)*1 -> 0 | D1136: 50504990 | E1136: =IF(ISNUMBER(SEARCH($I$1,F1136)),MAX($E$2:E1135)+1,0) -> 0 | F1136: Other Losses | H1136: =IFERROR(VLOOKUP(ROWS($H$3:H1136),E:F,2,0),"")
H1137: =IFERROR(VLOOKUP(ROWS($H$3:H1137),E:F,2,0),"")
H1138: =IFERROR(VLOOKUP(ROWS($H$3:H1138),E:F,2,0),"")
H1139: =IFERROR(VLOOKUP(ROWS($H$3:H1139),E:F,2,0),"")
H1140: =IFERROR(VLOOKUP(ROWS($H$3:H1140),E:F,2,0),"")
H1141: =IFERROR(VLOOKUP(ROWS($H$3:H1141),E:F,2,0),"")
H1142: =IFERROR(VLOOKUP(ROWS($H$3:H1142),E:F,2,0),"")
H1143: =IFERROR(VLOOKUP(ROWS($H$3:H1143),E:F,2,0),"")
H1144: =IFERROR(VLOOKUP(ROWS($H$3:H1144),E:F,2,0),"")
H1145: =IFERROR(VLOOKUP(ROWS($H$3:H1145),E:F,2,0),"")
H1146: =IFERROR(VLOOKUP(ROWS($H$3:H1146),E:F,2,0),"")
H1147: =IFERROR(VLOOKUP(ROWS($H$3:H1147),E:F,2,0),"")
H1148: =IFERROR(VLOOKUP(ROWS($H$3:H1148),E:F,2,0),"")
...
